{
  "comments": [
    {
      "key": {
        "uuid": "da33351e_61c24435",
        "filename": "utils/test/testapi/opnfv_testapi/db/api.py",
        "patchSetId": 4
      },
      "lineNbr": 10,
      "author": {
        "id": 2651
      },
      "writtenOn": "2017-09-30T01:58:51Z",
      "side": 1,
      "message": "After I tested it, I found it doesn\u0027t solve our problem, the error message is still the same as: AutoReconnect: [Errno 111] Connection refused",
      "revId": "6dd1648f72486bcffdcdf2e153b6823c7f7e21e7",
      "serverId": "bbac25d2-bf60-4904-9ba8-a72fc000d6c5",
      "unresolved": false
    }
  ]
}